<?xml version="1.0" encoding="utf-8"?>
<robot xmlns:xacro="http://www.ros.org/wiki/xacro" name="hand">
  <xacro:macro name="hand" params="connected_to:='' robot_name='' rpy:='0 0 0' xyz:='0 0 0' ">
    <xacro:unless value="${connected_to == ''}">
      <joint name="${robot_name}_hand_joint" type="fixed">
        <parent link="${connected_to}"/>
        <child link="${robot_name}_hand"/>
        <origin xyz="${xyz}" rpy="${rpy}"/>
        <!-- <limit effort="0.0" lower="0.0" upper="0.0" velocity="0.0"/> -->
      </joint>
    </xacro:unless>

    <link name="${robot_name}_hand">
      <visual>
        <geometry>
          <mesh filename="package://easy_panda_sim/meshes/visual/hand.dae"/>
        </geometry>
      </visual>
      <collision>
        <geometry>
          <mesh filename="package://easy_panda_sim/meshes/collision/hand.stl"/>
        </geometry>
      </collision>
      <inertial>
        <origin xyz="0 0 0" rpy="0 0 0"/>
        <mass value="0.68"/>
        <inertia ixx="0.1" ixy="0.0" ixz="0.0" iyy="0.1" iyz="0.0" izz="0.1"/>
      </inertial>
    </link>
    <link name="${robot_name}_leftfinger">
      <visual>
        <geometry>
          <mesh filename="package://easy_panda_sim/meshes/visual/finger.dae"/>
        </geometry>
      </visual>
      <collision>
        <geometry>
          <mesh filename="package://easy_panda_sim/meshes/collision/finger.stl"/>
        </geometry>
      </collision>
      <inertial>
        <origin xyz="0 0 0" rpy="0 0 0"/>
        <mass value="0.01"/>
        <inertia ixx="0.1" ixy="0.0" ixz="0.0" iyy="0.1" iyz="0.0" izz="0.1"/>
      </inertial>
    </link>
    <link name="${robot_name}_rightfinger">
      <visual>
        <origin xyz="0 0 0" rpy="0 0 ${pi}"/>
        <geometry>
          <mesh filename="package://easy_panda_sim/meshes/visual/finger.dae"/>
        </geometry>
      </visual>
      <collision>
        <origin xyz="0 0 0" rpy="0 0 ${pi}"/>
        <geometry>
          <mesh filename="package://easy_panda_sim/meshes/collision/finger.stl"/>
        </geometry>
      </collision>
      <inertial>
        <origin xyz="0 0 0" rpy="0 0 0"/>
        <mass value="0.01"/>
        <inertia ixx="0.1" ixy="0.0" ixz="0.0" iyy="0.1" iyz="0.0" izz="0.1"/>
      </inertial>
    </link>
    <link name="${robot_name}_tcp">
    </link>
    <joint name="${robot_name}_finger_joint1" type="prismatic">
      <parent link="${robot_name}_hand"/>
      <child link="${robot_name}_leftfinger"/>
      <origin xyz="0 0 0.0584" rpy="0 0 0"/>
      <axis xyz="0 1 0"/>
      <limit effort="20" lower="0.0" upper="0.04" velocity="0.2"/>
    </joint>
    <joint name="${robot_name}_finger_joint2" type="prismatic">
      <parent link="${robot_name}_hand"/>
      <child link="${robot_name}_rightfinger"/>
      <origin xyz="0 0 0.0584" rpy="0 0 0"/>
      <axis xyz="0 -1 0"/>
      <limit effort="20" lower="0.0" upper="0.04" velocity="0.2"/>
      <mimic joint="${robot_name}_finger_joint1" />
    </joint>
    <joint name="${robot_name}_tcp_joint" type="fixed">
      <parent link="${robot_name}_hand"/>
      <child link="${robot_name}_tcp"/>
      <origin xyz="0 0 0.12" rpy="0 0 0"/>
      <axis xyz="0 -1 0"/>
    </joint>
  </xacro:macro>
</robot>
